Workbook
Name band_name: Lookups!$B$19:$B$23
Name band_start: Lookups!$A$19:$A$23
Name f_atemp: Final_Dataset!$K$2:$K$1001
Name f_casual: Final_Dataset!$N$2:$N$1001
Name f_Casual_Share: Final_Dataset!$AC$2:$AC$1001
Name f_cnt: Final_Dataset!$P$2:$P$1001
Name f_DateTime: Final_Dataset!$R$2:$R$1001
Name f_Day_Name: Final_Dataset!$T$2:$T$1001
Name f_Day_Type: Final_Dataset!$U$2:$U$1001
Name f_Demand_Level: Final_Dataset!$AD$2:$AD$1001
Name f_dteday: Final_Dataset!$B$2:$B$1001
Name f_holiday: Final_Dataset!$G$2:$G$1001
Name f_hr: Final_Dataset!$F$2:$F$1001
Name f_hum: Final_Dataset!$L$2:$L$1001
Name f_Humidity_Band: Final_Dataset!$AA$2:$AA$1001
Name f_Month: Final_Dataset!$S$2:$S$1001
Name f_Peak_Hour: Final_Dataset!$AB$2:$AB$1001
Name f_Record_ID: Final_Dataset!$Q$2:$Q$1001
Name f_registered: Final_Dataset!$O$2:$O$1001
Name f_Season_Name: Final_Dataset!$W$2:$W$1001
Name f_temp: Final_Dataset!$J$2:$J$1001
Name f_Temp_Band: Final_Dataset!$Z$2:$Z$1001
Name f_Time_Band: Final_Dataset!$Y$2:$Y$1001
Name f_Visible: Final_Dataset!$AE$2:$AE$1001
Name f_Weather: Final_Dataset!$X$2:$X$1001
Name f_weathersit: Final_Dataset!$I$2:$I$1001
Name f_weekday: Final_Dataset!$H$2:$H$1001
Name f_windspeed: Final_Dataset!$M$2:$M$1001
Name f_Working_Day: Final_Dataset!$V$2:$V$1001
Name hum_band: Lookups!$B$33:$B$35
Name hum_from: Lookups!$A$33:$A$35
Name NativeTimeline_dteday: #N/A
Name Slicer_Day_Type: #N/A
Name Slicer_Weather: #N/A
Name tbl_season: Lookups!$A$12:$B$15
Name tbl_weather: Lookups!$A$5:$B$8
Name temp_band: Lookups!$B$27:$B$29
Name temp_from: Lookups!$A$27:$A$29

Sheet Cover
B2: Bike Sharing Demand Analysis
B3: NextHikes IT Solutions | Data Analysis with Excel
B7: Problem statement | C7: Understand how weather, time and holidays affect hourly bike rentals, and turn the findings into decisions for fleet availability, staffing and marketing.
B8: Data | C8: Three source files: Dataset 1 (time & weather, 610 rows), Dataset 2 (feels-like temp, humidity, wind, rentals, 610 rows), Dataset 3 (all fields, 390 rows). Combined: 1,000 hourly records, 1 Jan–14 Feb 2011.
B9: Data flow | C9: Dataset_1 + Dataset_2 → (merge on instant) → Dataset_A → (append Dataset_3) → Final_Dataset → Analysis / Stats / Anomalies / Forecast → Dashboard
B11: Sheet guide
B12: Dashboard | C12: Interactive one-page view: KPI cards, filters (day type, weather, month, time band, date range), charts, funnel and heatmap.
B13: Insights | C13: Key findings, recommendations and limitations in plain language.
B14: Analysis | C14: Pivot-style summaries by hour, weekday, working day, weather, time band, temperature, humidity, month and day, each with a chart.
B15: Stats | C15: Basic and text functions, COUNTIF/SUMIF, descriptive statistics and the correlation matrix.
B16: Anomalies | C16: Z-score anomaly detection per hour of day, with an adjustable threshold.
B17: Forecast | C17: 48-hour FORECAST.ETS forecast with a 95% confidence band and accuracy statistics.
B18: Final_Dataset | C18: Clean merged table (1,000 × 31) with engineered features. Excel Table "tblFinal".
B19: Dataset_A | C19: Dataset 1 merged with Dataset 2 on instant (INDEX/MATCH).
B20: Dataset_1 | C20: Source dataset 1, checked.
B21: Dataset_2 | C21: Source dataset 2, cleaned (index column removed, 11 blanks filled).
B22: Dataset_3 | C22: Source dataset 3, sorted and checked.
B23: Data_Quality | C23: Checks at every stage, cleaning steps and a small study of each dataset.
... B25: Dashboard_Calc | C25: Behind-the-scenes calculations for the Dashboard.
B27: Reading tips
C28: • Cells with a small red triangle have a comment: hover over them to read what the data means.
C29: • Blue numbers on a yellow background are inputs you can change (thresholds, forecast settings).
C30: • Green text marks values that were filled during cleaning.
C31: • Optional in Excel: select any cell in Final_Dataset > Table Design > Insert Slicer to add slicers; the Dashboard follows them through the Visible column.

Sheet Dashboard
C2: BIKE SHARING DEMAND DASHBOARD
C3: NextHikes IT Solutions | Hourly bike rentals, 1 Jan – 14 Feb 2011 | 1,000 records | Pick a filter below: every number, chart and the heatmap updates
B5: DAY TYPE | H5: WEATHER | N5: MONTH | T5: TIME BAND | Z5: FROM DATE | AF5: TO DATE | AL5: ▲ white boxes are filters
B6: All | H6: All | N6: All | T6: All | Z6: 40544 | AF6: 40588
C8: TOTAL RENTALS | H8: REGISTERED | M8: CASUAL | R8: AVG / HOUR | W8: PEAK HOUR | AB8: BUSIEST DAY | AG8: RAIN IMPACT | AL8: ANOMALIES
C9: =Dashboard_Calc!B13 -> 58304 | H9: =Dashboard_Calc!B14 -> 53383 | M9: =Dashboard_Calc!B15 -> 4921 | R9: =Dashboard_Calc!B17 -> 58.304 | W9: =Dashboard_Calc!B20 -> 5 PM | AB9: =Dashboard_Calc!B22 -> Thu | AG9: =Dashboard_Calc!B25 -> -0.46162623 | AL9: =Dashboard_Calc!B26 -> 7
B11: =TEXT(Dashboard_Calc!B16,"#,##0")&" hours in view" -> 1,000 hours in view | G11: =TEXT(Dashboard_Calc!B18,"0.0%")&" of rentals" -> 91.6% of rentals | L11: =TEXT(Dashboard_Calc!B19,"0.0%")&" of rentals" -> 8.4% of rentals | Q11: ="peak hours = "&TEXT(Dashboard_Calc!B27,"0%")&" of rentals" -> peak hours = 44% of rentals | V11: ="avg "&TEXT(Dashboard_Calc!B21,"0")&" rentals" -> avg 140 rentals | AA11: ="avg "&TEXT(Dashboard_Calc!B23,"0")&" / hour" -> avg 68 / hour | AF11: ="light rain vs clear" -> light rain vs clear | AK11: ="hours with Z-score ≥ "&Anomalies!B4 -> hours with Z-score ≥ 3
B13: Demand by Hour of Day | L13: Demand by Day of Week | V13: Daily Rentals Trend | AF13: Demand by Weather
B29: Heatmap: average rentals by day and hour (darker = busier) | AF29: Commute Funnel
C30: Hour → | D30: 0 | E30: 1 | F30: 2 | G30: 3 | H30: 4 | I30: 5 | J30: 6 | K30: 7 | L30: 8 | M30: 9 | N30: 10 | O30: 11 | P30: 12 | Q30: 13 | R30: 14 | S30: 15 | T30: 16 | U30: 17 | V30: 18 | W30: 19 | X30: 20 | Y30: 21 | Z30: 22 | AA30: 23
C31: Mon | D31: =IFERROR(AVERAGEIFS(f_cnt,f_Day_Type,Dashboard_Calc!$B$5,f_Weather,Dashboard_Calc!$B$6,f_Month,Dashboard_Calc!$B$7,f_Time_Band,Dashboard_Calc!$B$8,f_dteday,">="&Dashboard_Calc!$B$9,f_dteday,"<="&Dashboard_Calc!$B$10,f_Visible,1,f_hr,D$30,f_Day_Name,$C31),0) -> 9.5714286 | E31: =IFERROR(AVERAGEIFS(f_cnt,f_Day_Type,Dashboard_Calc!$B$5,f_Weather,Dashboard_Calc!$B$6,f_Month,Dashboard_Calc!$B$7,f_Time_Band,Dashboard_Calc!$B$8,f_dteday,">="&Dashboard_Calc!$B$9,f_dteday,"<="&Dashboard_Calc!$B$10,f_Visible,1,f_hr,E$30,f_Day_Name,$C31),0) -> 5.5714286 | F31: =IFERROR(AVERAGEIFS(f_cnt,f_Day_Type,Dashboard_Calc!$B$5,f_Weather,Dashboard_Calc!$B$6,f_Month,Dashboard_Calc!$B$7,f_Time_Band,Dashboard_Calc!$B$8,f_dteday,">="&Dashboard_Calc!$B$9,f_dteday,"<="&Dashboard_Calc!$B$10,f_Visible,1,f_hr,F$30,f_Day_Name,$C31),0) -> 3.4 | G31: =IFERROR(AVERAGEIFS(f_cnt,f_Day_Type,Dashboard_Calc!$B$5,f_Weather,Dashboard_Calc!$B$6,f_Month,Dashboard_Calc!$B$7,f_Time_Band,Dashboard_Calc!$B$8,f_dteday,">="&Dashboard_Calc!$B$9,f_dteday,"<="&Dashboard_Calc!$B$10,f_Visible,1,f_hr,G$30,f_Day_Name,$C31),0) -> 1.5 | H31: =IFERROR(AVERAGEIFS(f_cnt,f_Day_Type,Dashboard_Calc!$B$5,f_Weather,Dashboard_Calc!$B$6,f_Month,Dashboard_Calc!$B$7,f_Time_Band,Dashboard_Calc!$B$8,f_dteday,">="&Dashboard_Calc!$B$9,f_dteday,"<="&Dashboard_Calc!$B$10,f_Visible,1,f_hr,H$30,f_Day_Name,$C31),0) -> 2 | I31: =IFERROR(AVERAGEIFS(f_cnt,f_Day_Type,Dashboard_Calc!$B$5,f_Weather,Dashboard_Calc!$B$6,f_Month,Dashboard_Calc!$B$7,f_Time_Band,Dashboard_Calc!$B$8,f_dteday,">="&Dashboard_Calc!$B$9,f_dteday,"<="&Dashboard_Calc!$B$10,f_Visible,1,f_hr,I$30,f_Day_Name,$C31),0) -> 4.7142857 | J31: =IFERROR(AVERAGEIFS(f_cnt,f_Day_Type,Dashboard_Calc!$B$5,f_Weather,Dashboard_Calc!$B$6,f_Month,Dashboard_Calc!$B$7,f_Time_Band,Dashboard_Calc!$B$8,f_dteday,">="&Dashboard_Calc!$B$9,f_dteday,"<="&Dashboard_Calc!$B$10,f_Visible,1,f_hr,J$30,f_Day_Name,$C31),0) -> 24.857143 | K31: =IFERROR(AVERAGEIFS(f_cnt,f_Day_Type,Dashboard_Calc!$B$5,f_Weather,Dashboard_Calc!$B$6,f_Month,Dashboard_Calc!$B$7,f_Time_Band,Dashboard_Calc!$B$8,f_dteday,">="&Dashboard_Calc!$B$9,f_dteday,"<="&Dashboard_Calc!$B$10,f_Visible,1,f_hr,K$30,f_Day_Name,$C31),0) -> 71.857143 | ... AA31: =IFERROR(AVERAGEIFS(f_cnt,f_Day_Type,Dashboard_Calc!$B$5,f_Weather,Dashboard_Calc!$B$6,f_Month,Dashboard_Calc!$B$7,f_Time_Band,Dashboard_Calc!$B$8,f_dteday,">="&Dashboard_Calc!$B$9,f_dteday,"<="&Dashboard_Calc!$B$10,f_Visible,1,f_hr,AA$30,f_Day_Name,$C31),0) -> 16.666667 | AB31: Weekday commute peaks
C32: Tue | D32: =IFERROR(AVERAGEIFS(f_cnt,f_Day_Type,Dashboard_Calc!$B$5,f_Weather,Dashboard_Calc!$B$6,f_Month,Dashboard_Calc!$B$7,f_Time_Band,Dashboard_Calc!$B$8,f_dteday,">="&Dashboard_Calc!$B$9,f_dteday,"<="&Dashboard_Calc!$B$10,f_Visible,1,f_hr,D$30,f_Day_Name,$C32),0) -> 8.8 | E32: =IFERROR(AVERAGEIFS(f_cnt,f_Day_Type,Dashboard_Calc!$B$5,f_Weather,Dashboard_Calc!$B$6,f_Month,Dashboard_Calc!$B$7,f_Time_Band,Dashboard_Calc!$B$8,f_dteday,">="&Dashboard_Calc!$B$9,f_dteday,"<="&Dashboard_Calc!$B$10,f_Visible,1,f_hr,E$30,f_Day_Name,$C32),0) -> 3.4 | F32: =IFERROR(AVERAGEIFS(f_cnt,f_Day_Type,Dashboard_Calc!$B$5,f_Weather,Dashboard_Calc!$B$6,f_Month,Dashboard_Calc!$B$7,f_Time_Band,Dashboard_Calc!$B$8,f_dteday,">="&Dashboard_Calc!$B$9,f_dteday,"<="&Dashboard_Calc!$B$10,f_Visible,1,f_hr,F$30,f_Day_Name,$C32),0) -> 2 | G32: =IFERROR(AVERAGEIFS(f_cnt,f_Day_Type,Dashboard_Calc!$B$5,f_Weather,Dashboard_Calc!$B$6,f_Month,Dashboard_Calc!$B$7,f_Time_Band,Dashboard_Calc!$B$8,f_dteday,">="&Dashboard_Calc!$B$9,f_dteday,"<="&Dashboard_Calc!$B$10,f_Visible,1,f_hr,G$30,f_Day_Name,$C32),0) -> 1.5 | H32: =IFERROR(AVERAGEIFS(f_cnt,f_Day_Type,Dashboard_Calc!$B$5,f_Weather,Dashboard_Calc!$B$6,f_Month,Dashboard_Calc!$B$7,f_Time_Band,Dashboard_Calc!$B$8,f_dteday,">="&Dashboard_Calc!$B$9,f_dteday,"<="&Dashboard_Calc!$B$10,f_Visible,1,f_hr,H$30,f_Day_Name,$C32),0) -> 2 | I32: =IFERROR(AVERAGEIFS(f_cnt,f_Day_Type,Dashboard_Calc!$B$5,f_Weather,Dashboard_Calc!$B$6,f_Month,Dashboard_Calc!$B$7,f_Time_Band,Dashboard_Calc!$B$8,f_dteday,">="&Dashboard_Calc!$B$9,f_dteday,"<="&Dashboard_Calc!$B$10,f_Visible,1,f_hr,I$30,f_Day_Name,$C32),0) -> 4.8 | J32: =IFERROR(AVERAGEIFS(f_cnt,f_Day_Type,Dashboard_Calc!$B$5,f_Weather,Dashboard_Calc!$B$6,f_Month,Dashboard_Calc!$B$7,f_Time_Band,Dashboard_Calc!$B$8,f_dteday,">="&Dashboard_Calc!$B$9,f_dteday,"<="&Dashboard_Calc!$B$10,f_Visible,1,f_hr,J$30,f_Day_Name,$C32),0) -> 32 | K32: =IFERROR(AVERAGEIFS(f_cnt,f_Day_Type,Dashboard_Calc!$B$5,f_Weather,Dashboard_Calc!$B$6,f_Month,Dashboard_Calc!$B$7,f_Time_Band,Dashboard_Calc!$B$8,f_dteday,">="&Dashboard_Calc!$B$9,f_dteday,"<="&Dashboard_Calc!$B$10,f_Visible,1,f_hr,K$30,f_Day_Name,$C32),0) -> 90.6 | ... AA32: =IFERROR(AVERAGEIFS(f_cnt,f_Day_Type,Dashboard_Calc!$B$5,f_Weather,Dashboard_Calc!$B$6,f_Month,Dashboard_Calc!$B$7,f_Time_Band,Dashboard_Calc!$B$8,f_dteday,">="&Dashboard_Calc!$B$9,f_dteday,"<="&Dashboard_Calc!$B$10,f_Visible,1,f_hr,AA$30,f_Day_Name,$C32),0) -> 19.666667
C33: Wed | D33: =IFERROR(AVERAGEIFS(f_cnt,f_Day_Type,Dashboard_Calc!$B$5,f_Weather,Dashboard_Calc!$B$6,f_Month,Dashboard_Calc!$B$7,f_Time_Band,Dashboard_Calc!$B$8,f_dteday,">="&Dashboard_Calc!$B$9,f_dteday,"<="&Dashboard_Calc!$B$10,f_Visible,1,f_hr,D$30,f_Day_Name,$C33),0) -> 8.6666667 | E33: =IFERROR(AVERAGEIFS(f_cnt,f_Day_Type,Dashboard_Calc!$B$5,f_Weather,Dashboard_Calc!$B$6,f_Month,Dashboard_Calc!$B$7,f_Time_Band,Dashboard_Calc!$B$8,f_dteday,">="&Dashboard_Calc!$B$9,f_dteday,"<="&Dashboard_Calc!$B$10,f_Visible,1,f_hr,E$30,f_Day_Name,$C33),0) -> 5.6666667 | F33: =IFERROR(AVERAGEIFS(f_cnt,f_Day_Type,Dashboard_Calc!$B$5,f_Weather,Dashboard_Calc!$B$6,f_Month,Dashboard_Calc!$B$7,f_Time_Band,Dashboard_Calc!$B$8,f_dteday,">="&Dashboard_Calc!$B$9,f_dteday,"<="&Dashboard_Calc!$B$10,f_Visible,1,f_hr,F$30,f_Day_Name,$C33),0) -> 3.8333333 | G33: =IFERROR(AVERAGEIFS(f_cnt,f_Day_Type,Dashboard_Calc!$B$5,f_Weather,Dashboard_Calc!$B$6,f_Month,Dashboard_Calc!$B$7,f_Time_Band,Dashboard_Calc!$B$8,f_dteday,">="&Dashboard_Calc!$B$9,f_dteday,"<="&Dashboard_Calc!$B$10,f_Visible,1,f_hr,G$30,f_Day_Name,$C33),0) -> 1.5 | H33: =IFERROR(AVERAGEIFS(f_cnt,f_Day_Type,Dashboard_Calc!$B$5,f_Weather,Dashboard_Calc!$B$6,f_Month,Dashboard_Calc!$B$7,f_Time_Band,Dashboard_Calc!$B$8,f_dteday,">="&Dashboard_Calc!$B$9,f_dteday,"<="&Dashboard_Calc!$B$10,f_Visible,1,f_hr,H$30,f_Day_Name,$C33),0) -> 1.6666667 | I33: =IFERROR(AVERAGEIFS(f_cnt,f_Day_Type,Dashboard_Calc!$B$5,f_Weather,Dashboard_Calc!$B$6,f_Month,Dashboard_Calc!$B$7,f_Time_Band,Dashboard_Calc!$B$8,f_dteday,">="&Dashboard_Calc!$B$9,f_dteday,"<="&Dashboard_Calc!$B$10,f_Visible,1,f_hr,I$30,f_Day_Name,$C33),0) -> 4.3333333 | J33: =IFERROR(AVERAGEIFS(f_cnt,f_Day_Type,Dashboard_Calc!$B$5,f_Weather,Dashboard_Calc!$B$6,f_Month,Dashboard_Calc!$B$7,f_Time_Band,Dashboard_Calc!$B$8,f_dteday,">="&Dashboard_Calc!$B$9,f_dteday,"<="&Dashboard_Calc!$B$10,f_Visible,1,f_hr,J$30,f_Day_Name,$C33),0) -> 25 | K33: =IFERROR(AVERAGEIFS(f_cnt,f_Day_Type,Dashboard_Calc!$B$5,f_Weather,Dashboard_Calc!$B$6,f_Month,Dashboard_Calc!$B$7,f_Time_Band,Dashboard_Calc!$B$8,f_dteday,">="&Dashboard_Calc!$B$9,f_dteday,"<="&Dashboard_Calc!$B$10,f_Visible,1,f_hr,K$30,f_Day_Name,$C33),0) -> 68.333333 | ... AA33: =IFERROR(AVERAGEIFS(f_cnt,f_Day_Type,Dashboard_Calc!$B$5,f_Weather,Dashboard_Calc!$B$6,f_Month,Dashboard_Calc!$B$7,f_Time_Band,Dashboard_Calc!$B$8,f_dteday,">="&Dashboard_Calc!$B$9,f_dteday,"<="&Dashboard_Calc!$B$10,f_Visible,1,f_hr,AA$30,f_Day_Name,$C33),0) -> 27.2
C34: Thu | D34: =IFERROR(AVERAGEIFS(f_cnt,f_Day_Type,Dashboard_Calc!$B$5,f_Weather,Dashboard_Calc!$B$6,f_Month,Dashboard_Calc!$B$7,f_Time_Band,Dashboard_Calc!$B$8,f_dteday,">="&Dashboard_Calc!$B$9,f_dteday,"<="&Dashboard_Calc!$B$10,f_Visible,1,f_hr,D$30,f_Day_Name,$C34),0) -> 11.8 | E34: =IFERROR(AVERAGEIFS(f_cnt,f_Day_Type,Dashboard_Calc!$B$5,f_Weather,Dashboard_Calc!$B$6,f_Month,Dashboard_Calc!$B$7,f_Time_Band,Dashboard_Calc!$B$8,f_dteday,">="&Dashboard_Calc!$B$9,f_dteday,"<="&Dashboard_Calc!$B$10,f_Visible,1,f_hr,E$30,f_Day_Name,$C34),0) -> 4.6 | F34: =IFERROR(AVERAGEIFS(f_cnt,f_Day_Type,Dashboard_Calc!$B$5,f_Weather,Dashboard_Calc!$B$6,f_Month,Dashboard_Calc!$B$7,f_Time_Band,Dashboard_Calc!$B$8,f_dteday,">="&Dashboard_Calc!$B$9,f_dteday,"<="&Dashboard_Calc!$B$10,f_Visible,1,f_hr,F$30,f_Day_Name,$C34),0) -> 2.2 | G34: =IFERROR(AVERAGEIFS(f_cnt,f_Day_Type,Dashboard_Calc!$B$5,f_Weather,Dashboard_Calc!$B$6,f_Month,Dashboard_Calc!$B$7,f_Time_Band,Dashboard_Calc!$B$8,f_dteday,">="&Dashboard_Calc!$B$9,f_dteday,"<="&Dashboard_Calc!$B$10,f_Visible,1,f_hr,G$30,f_Day_Name,$C34),0) -> 1.6666667 | H34: =IFERROR(AVERAGEIFS(f_cnt,f_Day_Type,Dashboard_Calc!$B$5,f_Weather,Dashboard_Calc!$B$6,f_Month,Dashboard_Calc!$B$7,f_Time_Band,Dashboard_Calc!$B$8,f_dteday,">="&Dashboard_Calc!$B$9,f_dteday,"<="&Dashboard_Calc!$B$10,f_Visible,1,f_hr,H$30,f_Day_Name,$C34),0) -> 1.75 | I34: =IFERROR(AVERAGEIFS(f_cnt,f_Day_Type,Dashboard_Calc!$B$5,f_Weather,Dashboard_Calc!$B$6,f_Month,Dashboard_Calc!$B$7,f_Time_Band,Dashboard_Calc!$B$8,f_dteday,">="&Dashboard_Calc!$B$9,f_dteday,"<="&Dashboard_Calc!$B$10,f_Visible,1,f_hr,I$30,f_Day_Name,$C34),0) -> 4.2 | J34: =IFERROR(AVERAGEIFS(f_cnt,f_Day_Type,Dashboard_Calc!$B$5,f_Weather,Dashboard_Calc!$B$6,f_Month,Dashboard_Calc!$B$7,f_Time_Band,Dashboard_Calc!$B$8,f_dteday,">="&Dashboard_Calc!$B$9,f_dteday,"<="&Dashboard_Calc!$B$10,f_Visible,1,f_hr,J$30,f_Day_Name,$C34),0) -> 32.8 | K34: =IFERROR(AVERAGEIFS(f_cnt,f_Day_Type,Dashboard_Calc!$B$5,f_Weather,Dashboard_Calc!$B$6,f_Month,Dashboard_Calc!$B$7,f_Time_Band,Dashboard_Calc!$B$8,f_dteday,">="&Dashboard_Calc!$B$9,f_dteday,"<="&Dashboard_Calc!$B$10,f_Visible,1,f_hr,K$30,f_Day_Name,$C34),0) -> 90.8 | ... AA34: =IFERROR(AVERAGEIFS(f_cnt,f_Day_Type,Dashboard_Calc!$B$5,f_Weather,Dashboard_Calc!$B$6,f_Month,Dashboard_Calc!$B$7,f_Time_Band,Dashboard_Calc!$B$8,f_dteday,">="&Dashboard_Calc!$B$9,f_dteday,"<="&Dashboard_Calc!$B$10,f_Visible,1,f_hr,AA$30,f_Day_Name,$C34),0) -> 26.166667
C35: Fri | D35: =IFERROR(AVERAGEIFS(f_cnt,f_Day_Type,Dashboard_Calc!$B$5,f_Weather,Dashboard_Calc!$B$6,f_Month,Dashboard_Calc!$B$7,f_Time_Band,Dashboard_Calc!$B$8,f_dteday,">="&Dashboard_Calc!$B$9,f_dteday,"<="&Dashboard_Calc!$B$10,f_Visible,1,f_hr,D$30,f_Day_Name,$C35),0) -> 14.666667 | E35: =IFERROR(AVERAGEIFS(f_cnt,f_Day_Type,Dashboard_Calc!$B$5,f_Weather,Dashboard_Calc!$B$6,f_Month,Dashboard_Calc!$B$7,f_Time_Band,Dashboard_Calc!$B$8,f_dteday,">="&Dashboard_Calc!$B$9,f_dteday,"<="&Dashboard_Calc!$B$10,f_Visible,1,f_hr,E$30,f_Day_Name,$C35),0) -> 5.8333333 | F35: =IFERROR(AVERAGEIFS(f_cnt,f_Day_Type,Dashboard_Calc!$B$5,f_Weather,Dashboard_Calc!$B$6,f_Month,Dashboard_Calc!$B$7,f_Time_Band,Dashboard_Calc!$B$8,f_dteday,">="&Dashboard_Calc!$B$9,f_dteday,"<="&Dashboard_Calc!$B$10,f_Visible,1,f_hr,F$30,f_Day_Name,$C35),0) -> 1.6666667 | G35: =IFERROR(AVERAGEIFS(f_cnt,f_Day_Type,Dashboard_Calc!$B$5,f_Weather,Dashboard_Calc!$B$6,f_Month,Dashboard_Calc!$B$7,f_Time_Band,Dashboard_Calc!$B$8,f_dteday,">="&Dashboard_Calc!$B$9,f_dteday,"<="&Dashboard_Calc!$B$10,f_Visible,1,f_hr,G$30,f_Day_Name,$C35),0) -> 1 | H35: =IFERROR(AVERAGEIFS(f_cnt,f_Day_Type,Dashboard_Calc!$B$5,f_Weather,Dashboard_Calc!$B$6,f_Month,Dashboard_Calc!$B$7,f_Time_Band,Dashboard_Calc!$B$8,f_dteday,">="&Dashboard_Calc!$B$9,f_dteday,"<="&Dashboard_Calc!$B$10,f_Visible,1,f_hr,H$30,f_Day_Name,$C35),0) -> 1 | I35: =IFERROR(AVERAGEIFS(f_cnt,f_Day_Type,Dashboard_Calc!$B$5,f_Weather,Dashboard_Calc!$B$6,f_Month,Dashboard_Calc!$B$7,f_Time_Band,Dashboard_Calc!$B$8,f_dteday,">="&Dashboard_Calc!$B$9,f_dteday,"<="&Dashboard_Calc!$B$10,f_Visible,1,f_hr,I$30,f_Day_Name,$C35),0) -> 5.5 | J35: =IFERROR(AVERAGEIFS(f_cnt,f_Day_Type,Dashboard_Calc!$B$5,f_Weather,Dashboard_Calc!$B$6,f_Month,Dashboard_Calc!$B$7,f_Time_Band,Dashboard_Calc!$B$8,f_dteday,">="&Dashboard_Calc!$B$9,f_dteday,"<="&Dashboard_Calc!$B$10,f_Visible,1,f_hr,J$30,f_Day_Name,$C35),0) -> 24.333333 | K35: =IFERROR(AVERAGEIFS(f_cnt,f_Day_Type,Dashboard_Calc!$B$5,f_Weather,Dashboard_Calc!$B$6,f_Month,Dashboard_Calc!$B$7,f_Time_Band,Dashboard_Calc!$B$8,f_dteday,">="&Dashboard_Calc!$B$9,f_dteday,"<="&Dashboard_Calc!$B$10,f_Visible,1,f_hr,K$30,f_Day_Name,$C35),0) -> 73.833333 | ... AA35: =IFERROR(AVERAGEIFS(f_cnt,f_Day_Type,Dashboard_Calc!$B$5,f_Weather,Dashboard_Calc!$B$6,f_Month,Dashboard_Calc!$B$7,f_Time_Band,Dashboard_Calc!$B$8,f_dteday,">="&Dashboard_Calc!$B$9,f_dteday,"<="&Dashboard_Calc!$B$10,f_Visible,1,f_hr,AA$30,f_Day_Name,$C35),0) -> 29.333333
C36: Sat | D36: =IFERROR(AVERAGEIFS(f_cnt,f_Day_Type,Dashboard_Calc!$B$5,f_Weather,Dashboard_Calc!$B$6,f_Month,Dashboard_Calc!$B$7,f_Time_Band,Dashboard_Calc!$B$8,f_dteday,">="&Dashboard_Calc!$B$9,f_dteday,"<="&Dashboard_Calc!$B$10,f_Visible,1,f_hr,D$30,f_Day_Name,$C36),0) -> 25.571429 | E36: =IFERROR(AVERAGEIFS(f_cnt,f_Day_Type,Dashboard_Calc!$B$5,f_Weather,Dashboard_Calc!$B$6,f_Month,Dashboard_Calc!$B$7,f_Time_Band,Dashboard_Calc!$B$8,f_dteday,">="&Dashboard_Calc!$B$9,f_dteday,"<="&Dashboard_Calc!$B$10,f_Visible,1,f_hr,E$30,f_Day_Name,$C36),0) -> 21.428571 | F36: =IFERROR(AVERAGEIFS(f_cnt,f_Day_Type,Dashboard_Calc!$B$5,f_Weather,Dashboard_Calc!$B$6,f_Month,Dashboard_Calc!$B$7,f_Time_Band,Dashboard_Calc!$B$8,f_dteday,">="&Dashboard_Calc!$B$9,f_dteday,"<="&Dashboard_Calc!$B$10,f_Visible,1,f_hr,F$30,f_Day_Name,$C36),0) -> 16.857143 | G36: =IFERROR(AVERAGEIFS(f_cnt,f_Day_Type,Dashboard_Calc!$B$5,f_Weather,Dashboard_Calc!$B$6,f_Month,Dashboard_Calc!$B$7,f_Time_Band,Dashboard_Calc!$B$8,f_dteday,">="&Dashboard_Calc!$B$9,f_dteday,"<="&Dashboard_Calc!$B$10,f_Visible,1,f_hr,G$30,f_Day_Name,$C36),0) -> 9.1428571 | H36: =IFERROR(AVERAGEIFS(f_cnt,f_Day_Type,Dashboard_Calc!$B$5,f_Weather,Dashboard_Calc!$B$6,f_Month,Dashboard_Calc!$B$7,f_Time_Band,Dashboard_Calc!$B$8,f_dteday,">="&Dashboard_Calc!$B$9,f_dteday,"<="&Dashboard_Calc!$B$10,f_Visible,1,f_hr,H$30,f_Day_Name,$C36),0) -> 3.5714286 | I36: =IFERROR(AVERAGEIFS(f_cnt,f_Day_Type,Dashboard_Calc!$B$5,f_Weather,Dashboard_Calc!$B$6,f_Month,Dashboard_Calc!$B$7,f_Time_Band,Dashboard_Calc!$B$8,f_dteday,">="&Dashboard_Calc!$B$9,f_dteday,"<="&Dashboard_Calc!$B$10,f_Visible,1,f_hr,I$30,f_Day_Name,$C36),0) -> 3.4 | J36: =IFERROR(AVERAGEIFS(f_cnt,f_Day_Type,Dashboard_Calc!$B$5,f_Weather,Dashboard_Calc!$B$6,f_Month,Dashboard_Calc!$B$7,f_Time_Band,Dashboard_Calc!$B$8,f_dteday,">="&Dashboard_Calc!$B$9,f_dteday,"<="&Dashboard_Calc!$B$10,f_Visible,1,f_hr,J$30,f_Day_Name,$C36),0) -> 2.4285714 | K36: =IFERROR(AVERAGEIFS(f_cnt,f_Day_Type,Dashboard_Calc!$B$5,f_Weather,Dashboard_Calc!$B$6,f_Month,Dashboard_Calc!$B$7,f_Time_Band,Dashboard_Calc!$B$8,f_dteday,">="&Dashboard_Calc!$B$9,f_dteday,"<="&Dashboard_Calc!$B$10,f_Visible,1,f_hr,K$30,f_Day_Name,$C36),0) -> 7.1428571 | ... AA36: =IFERROR(AVERAGEIFS(f_cnt,f_Day_Type,Dashboard_Calc!$B$5,f_Weather,Dashboard_Calc!$B$6,f_Month,Dashboard_Calc!$B$7,f_Time_Band,Dashboard_Calc!$B$8,f_dteday,">="&Dashboard_Calc!$B$9,f_dteday,"<="&Dashboard_Calc!$B$10,f_Visible,1,f_hr,AA$30,f_Day_Name,$C36),0) -> 37.428571 | AB36: Weekend midday leisure
C37: Sun | D37: =IFERROR(AVERAGEIFS(f_cnt,f_Day_Type,Dashboard_Calc!$B$5,f_Weather,Dashboard_Calc!$B$6,f_Month,Dashboard_Calc!$B$7,f_Time_Band,Dashboard_Calc!$B$8,f_dteday,">="&Dashboard_Calc!$B$9,f_dteday,"<="&Dashboard_Calc!$B$10,f_Visible,1,f_hr,D$30,f_Day_Name,$C37),0) -> 30.571429 | E37: =IFERROR(AVERAGEIFS(f_cnt,f_Day_Type,Dashboard_Calc!$B$5,f_Weather,Dashboard_Calc!$B$6,f_Month,Dashboard_Calc!$B$7,f_Time_Band,Dashboard_Calc!$B$8,f_dteday,">="&Dashboard_Calc!$B$9,f_dteday,"<="&Dashboard_Calc!$B$10,f_Visible,1,f_hr,E$30,f_Day_Name,$C37),0) -> 23.142857 | F37: =IFERROR(AVERAGEIFS(f_cnt,f_Day_Type,Dashboard_Calc!$B$5,f_Weather,Dashboard_Calc!$B$6,f_Month,Dashboard_Calc!$B$7,f_Time_Band,Dashboard_Calc!$B$8,f_dteday,">="&Dashboard_Calc!$B$9,f_dteday,"<="&Dashboard_Calc!$B$10,f_Visible,1,f_hr,F$30,f_Day_Name,$C37),0) -> 15 | G37: =IFERROR(AVERAGEIFS(f_cnt,f_Day_Type,Dashboard_Calc!$B$5,f_Weather,Dashboard_Calc!$B$6,f_Month,Dashboard_Calc!$B$7,f_Time_Band,Dashboard_Calc!$B$8,f_dteday,">="&Dashboard_Calc!$B$9,f_dteday,"<="&Dashboard_Calc!$B$10,f_Visible,1,f_hr,G$30,f_Day_Name,$C37),0) -> 9 | H37: =IFERROR(AVERAGEIFS(f_cnt,f_Day_Type,Dashboard_Calc!$B$5,f_Weather,Dashboard_Calc!$B$6,f_Month,Dashboard_Calc!$B$7,f_Time_Band,Dashboard_Calc!$B$8,f_dteday,">="&Dashboard_Calc!$B$9,f_dteday,"<="&Dashboard_Calc!$B$10,f_Visible,1,f_hr,H$30,f_Day_Name,$C37),0) -> 1.6666667 | I37: =IFERROR(AVERAGEIFS(f_cnt,f_Day_Type,Dashboard_Calc!$B$5,f_Weather,Dashboard_Calc!$B$6,f_Month,Dashboard_Calc!$B$7,f_Time_Band,Dashboard_Calc!$B$8,f_dteday,">="&Dashboard_Calc!$B$9,f_dteday,"<="&Dashboard_Calc!$B$10,f_Visible,1,f_hr,I$30,f_Day_Name,$C37),0) -> 2 | J37: =IFERROR(AVERAGEIFS(f_cnt,f_Day_Type,Dashboard_Calc!$B$5,f_Weather,Dashboard_Calc!$B$6,f_Month,Dashboard_Calc!$B$7,f_Time_Band,Dashboard_Calc!$B$8,f_dteday,">="&Dashboard_Calc!$B$9,f_dteday,"<="&Dashboard_Calc!$B$10,f_Visible,1,f_hr,J$30,f_Day_Name,$C37),0) -> 1.8333333 | K37: =IFERROR(AVERAGEIFS(f_cnt,f_Day_Type,Dashboard_Calc!$B$5,f_Weather,Dashboard_Calc!$B$6,f_Month,Dashboard_Calc!$B$7,f_Time_Band,Dashboard_Calc!$B$8,f_dteday,">="&Dashboard_Calc!$B$9,f_dteday,"<="&Dashboard_Calc!$B$10,f_Visible,1,f_hr,K$30,f_Day_Name,$C37),0) -> 3.7142857 | ... AA37: =IFERROR(AVERAGEIFS(f_cnt,f_Day_Type,Dashboard_Calc!$B$5,f_Weather,Dashboard_Calc!$B$6,f_Month,Dashboard_Calc!$B$7,f_Time_Band,Dashboard_Calc!$B$8,f_dteday,">="&Dashboard_Calc!$B$9,f_dteday,"<="&Dashboard_Calc!$B$10,f_Visible,1,f_hr,AA$30,f_Day_Name,$C37),0) -> 19.142857
B39: Key insights
B40: 1 | C40: ="Commuters drive demand: registered riders are "&TEXT(Stats!C14,"0%")&" of all rentals." -> Commuters drive demand: registered riders are 92% of all rentals. | Q40: 5 | R40: ="Light rain/snow cuts hourly rentals by about "&TEXT(-Dashboard_Calc!B25,"0%")&" vs clear weather." -> Light rain/snow cuts hourly rentals by about 46% vs clear weather.
B41: 2 | C41: ="Two daily peaks, 8 AM and 5 PM; the 5 PM hour averages "&TEXT(MAX(Analysis!E6:E29),"0")&" rentals." -> Two daily peaks, 8 AM and 5 PM; the 5 PM hour averages 140 rentals. | Q41: 6 | R41: ="Warmer hours sell more: Warm band averages "&TEXT(Analysis!E104, "0")&" vs "&TEXT(Analysis!E102, "0")&" in Cold." -> Warmer hours sell more: Warm band averages 86 vs 48 in Cold.
B42: 3 | C42: ="Weekday commute hours carry "&TEXT(Stats!C20,"0%")&" of all rentals." -> Weekday commute hours carry 44% of all rentals. | Q42: 7 | R42: ="Night (0-5 AM) averages under 10 rentals/hour: best window for rebalancing and repairs." -> Night (0-5 AM) averages under 10 rentals/hour: best window for rebalancing and repairs.
B43: 4 | C43: ="Weekends bring 2-3x more casual riders, mostly 11 AM to 4 PM." -> Weekends bring 2-3x more casual riders, mostly 11 AM to 4 PM. | Q43: 8 | R43: ="Forecast: the next 24 hours repeat the commute shape (see Forecast sheet)." -> Forecast: the next 24 hours repeat the commute shape (see Forecast sheet).
B46: Data: NextHikes Project 1 datasets 1-3 merged on instant. Averages are rentals per hourly record; temp/humidity are normalised source values. Formulas only, works in Excel for Mac and Windows without macros. Detail: Analysis, Stats, Anomalies, Forecast sheets.

Sheet Insights
A1: Findings, Recommendations & Limitations
A2: Plain-language summary for the reader and the source for the summary document / PPT. Numbers in brackets are live from the analysis sheets.
A4: Key findings
A5: 1 | B5: ="Registered (subscribed) riders generate "&TEXT(Stats!C14,"0.0%")&" of all "&TEXT(Stats!C5,"#,##0")&" rentals; casual riders only "&TEXT(1-Stats!C14,"0.0%")&"." -> Registered (subscribed) riders generate 91.6% of all 58,304 rentals; casual riders only 8.4%.
A6: 2 | B6: ="Demand follows a commuter pattern: peaks at 8 AM and 5 PM on weekdays; weekday peak hours hold "&TEXT(Stats!C20,"0%")&" of all rentals." -> Demand follows a commuter pattern: peaks at 8 AM and 5 PM on weekdays; weekday peak hours hold 44% of all rentals.
A7: 3 | B7: ="Weekdays average "&TEXT(Stats!C17,"0.0")&" rentals per hour vs "&TEXT(Stats!C18,"0.0")&" at weekends, but casual riding more than doubles at weekends (leisure use)." -> Weekdays average 63.3 rentals per hour vs 48.1 at weekends, but casual riding more than doubles at weekends (leisure use).
A8: 4 | B8: ="Weather matters most when it rains: Light Rain/Snow hours average "&TEXT(Analysis!E70,"0")&" rentals vs "&TEXT(Analysis!E68,"0")&" in Clear hours." -> Weather matters most when it rains: Light Rain/Snow hours average 33 rentals vs 62 in Clear hours.
A9: 5 | B9: ="Temperature and humidity have weak correlations with demand (temp "&TEXT(Stats!C22,"0.00")&", humidity "&TEXT(Stats!C23,"0.00")&"); time of day explains far more." -> Temperature and humidity have weak correlations with demand (temp 0.23, humidity -0.25); time of day explains far more.
A10: 6 | B10: ="Night hours (0–5 AM) average "&TEXT(Analysis!E85,"0.0")&" rentals per hour, the quietest period." -> Night hours (0–5 AM) average 8.0 rentals per hour, the quietest period.
A11: 7 | B11: ="Anomaly check flagged "&Anomalies!B7+Anomalies!B8&" of 1,000 hours as unusual for their hour of day; they are real busy hours, so they are kept." -> Anomaly check flagged 7 of 1,000 hours as unusual for their hour of day; they are real busy hours, so they are kept.
A12: 8 | B12: ="The FORECAST.ETS model (24-hour seasonality) has MASE "&TEXT(Forecast!E7,"0.00")&" and a typical error (MAE) of "&TEXT(Forecast!E9,"0")&" rentals per hour." -> The FORECAST.ETS model (24-hour seasonality) has MASE 0.98 and a typical error (MAE) of 21 rentals per hour.
A14: Recommendations
A15: 1 | B15: Guarantee bike availability at stations near offices and transit hubs before 8 AM and 5 PM on weekdays; this is where most revenue is.
A16: 2 | B16: Use the night window (0–5 AM) for rebalancing, maintenance and battery/repair work: demand is lowest then.
A17: 3 | B17: Grow casual and weekend use with leisure offers (weekend day passes, park/tourist routes), since casual riders are the weekend segment.
A18: 4 | B18: Plan for rain: reduce field staff and shift rebalancing on rainy days; push "ride after the rain" offers when forecasts show clearing.
A19: 5 | B19: Use the hourly forecast to schedule staff and pre-position bikes for the next day.
A20: 6 | B20: Collect more data (full year, all seasons) before deciding on seasonal pricing or fleet size.
A22: Limitations
A23: 1 | B23: Only 1,000 hours (1 Jan–14 Feb 2011), all in season 1 (winter/spring), so seasonal effects cannot be tested.
A24: 2 | B24: 64 hours are missing from the timeline in the source data; 14 Feb is a partial day.
A25: 3 | B25: temp, atemp, humidity and windspeed are normalised with unknown units, so results are relative (no °C/°F).
A26: 4 | B26: Heavy Rain appears in a single hour: no conclusion can be drawn for that category.
A27: 5 | B27: Correlation shows association, not causation.

Sheet Analysis
A1: Demand Analysis
A2: Pivot-style summaries built with AVERAGEIFS / SUMIFS / COUNTIFS on the final dataset (brief task 4). Each table has a chart and a comment with the takeaway.
B4: 1. Demand by Hour of Day
B5: Hour | C5: Avg Casual | D5: Avg Registered | E5: Avg Total | F5: Hours | G5: Total Rentals | H5: Casual Share
B6: 0 | C6: =IFERROR(AVERAGEIFS(f_casual,f_hr,$B6),0) -> 1.7209302 | D6: =IFERROR(AVERAGEIFS(f_registered,f_hr,$B6),0) -> 14.627907 | E6: =IFERROR(AVERAGEIFS(f_cnt,f_hr,$B6),0) -> 16.348837 | F6: =COUNTIFS(f_hr,$B6) -> 43 | G6: =SUMIFS(f_cnt,f_hr,$B6) -> 703 | H6: =IFERROR(SUMIFS(f_casual,f_hr,$B6)/SUMIFS(f_cnt,f_hr,$B6),0) -> 0.10526316
B7: 1 | C7: =IFERROR(AVERAGEIFS(f_casual,f_hr,$B7),0) -> 1.1162791 | D7: =IFERROR(AVERAGEIFS(f_registered,f_hr,$B7),0) -> 9.5813953 | E7: =IFERROR(AVERAGEIFS(f_cnt,f_hr,$B7),0) -> 10.697674 | F7: =COUNTIFS(f_hr,$B7) -> 43 | G7: =SUMIFS(f_cnt,f_hr,$B7) -> 460 | H7: =IFERROR(SUMIFS(f_casual,f_hr,$B7)/SUMIFS(f_cnt,f_hr,$B7),0) -> 0.10434783
B8: 2 | C8: =IFERROR(AVERAGEIFS(f_casual,f_hr,$B8),0) -> 0.80487805 | D8: =IFERROR(AVERAGEIFS(f_registered,f_hr,$B8),0) -> 6.3658537 | E8: =IFERROR(AVERAGEIFS(f_cnt,f_hr,$B8),0) -> 7.1707317 | F8: =COUNTIFS(f_hr,$B8) -> 41 | G8: =SUMIFS(f_cnt,f_hr,$B8) -> 294 | H8: =IFERROR(SUMIFS(f_casual,f_hr,$B8)/SUMIFS(f_cnt,f_hr,$B8),0) -> 0.1122449
B9: 3 | C9: =IFERROR(AVERAGEIFS(f_casual,f_hr,$B9),0) -> 1.0967742 | D9: =IFERROR(AVERAGEIFS(f_registered,f_hr,$B9),0) -> 3.7741935 | E9: =IFERROR(AVERAGEIFS(f_cnt,f_hr,$B9),0) -> 4.8709677 | F9: =COUNTIFS(f_hr,$B9) -> 31 | G9: =SUMIFS(f_cnt,f_hr,$B9) -> 151 | H9: =IFERROR(SUMIFS(f_casual,f_hr,$B9)/SUMIFS(f_cnt,f_hr,$B9),0) -> 0.22516556
B10: 4 | C10: =IFERROR(AVERAGEIFS(f_casual,f_hr,$B10),0) -> 0.21875 | D10: =IFERROR(AVERAGEIFS(f_registered,f_hr,$B10),0) -> 1.9375 | E10: =IFERROR(AVERAGEIFS(f_cnt,f_hr,$B10),0) -> 2.15625 | F10: =COUNTIFS(f_hr,$B10) -> 32 | G10: =SUMIFS(f_cnt,f_hr,$B10) -> 69 | H10: =IFERROR(SUMIFS(f_casual,f_hr,$B10)/SUMIFS(f_cnt,f_hr,$B10),0) -> 0.10144928
B11: 5 | C11: =IFERROR(AVERAGEIFS(f_casual,f_hr,$B11),0) -> 0.076923077 | D11: =IFERROR(AVERAGEIFS(f_registered,f_hr,$B11),0) -> 4.1282051 | E11: =IFERROR(AVERAGEIFS(f_cnt,f_hr,$B11),0) -> 4.2051282 | F11: =COUNTIFS(f_hr,$B11) -> 39 | G11: =SUMIFS(f_cnt,f_hr,$B11) -> 164 | H11: =IFERROR(SUMIFS(f_casual,f_hr,$B11)/SUMIFS(f_cnt,f_hr,$B11),0) -> 0.018292683
B12: 6 | C12: =IFERROR(AVERAGEIFS(f_casual,f_hr,$B12),0) -> 0.5 | D12: =IFERROR(AVERAGEIFS(f_registered,f_hr,$B12),0) -> 19.071429 | E12: =IFERROR(AVERAGEIFS(f_cnt,f_hr,$B12),0) -> 19.571429 | F12: =COUNTIFS(f_hr,$B12) -> 42 | G12: =SUMIFS(f_cnt,f_hr,$B12) -> 822 | H12: =IFERROR(SUMIFS(f_casual,f_hr,$B12)/SUMIFS(f_cnt,f_hr,$B12),0) -> 0.025547445
B13: 7 | C13: =IFERROR(AVERAGEIFS(f_casual,f_hr,$B13),0) -> 1.4883721 | D13: =IFERROR(AVERAGEIFS(f_registered,f_hr,$B13),0) -> 52.906977 | E13: =IFERROR(AVERAGEIFS(f_cnt,f_hr,$B13),0) -> 54.395349 | F13: =COUNTIFS(f_hr,$B13) -> 43 | G13: =SUMIFS(f_cnt,f_hr,$B13) -> 2339 | H13: =IFERROR(SUMIFS(f_casual,f_hr,$B13)/SUMIFS(f_cnt,f_hr,$B13),0) -> 0.027362121
B14: 8 | C14: =IFERROR(AVERAGEIFS(f_casual,f_hr,$B14),0) -> 3.0238095 | D14: =IFERROR(AVERAGEIFS(f_registered,f_hr,$B14),0) -> 125.2619 | E14: =IFERROR(AVERAGEIFS(f_cnt,f_hr,$B14),0) -> 128.28571 | F14: =COUNTIFS(f_hr,$B14) -> 42 | G14: =SUMIFS(f_cnt,f_hr,$B14) -> 5388 | H14: =IFERROR(SUMIFS(f_casual,f_hr,$B14)/SUMIFS(f_cnt,f_hr,$B14),0) -> 0.023570898
B15: 9 | C15: =IFERROR(AVERAGEIFS(f_casual,f_hr,$B15),0) -> 4.0952381 | D15: =IFERROR(AVERAGEIFS(f_registered,f_hr,$B15),0) -> 83.333333 | E15: =IFERROR(AVERAGEIFS(f_cnt,f_hr,$B15),0) -> 87.428571 | F15: =COUNTIFS(f_hr,$B15) -> 42 | G15: =SUMIFS(f_cnt,f_hr,$B15) -> 3672 | H15: =IFERROR(SUMIFS(f_casual,f_hr,$B15)/SUMIFS(f_cnt,f_hr,$B15),0) -> 0.046840959
B16: 10 | C16: =IFERROR(AVERAGEIFS(f_casual,f_hr,$B16),0) -> 5.1428571 | D16: =IFERROR(AVERAGEIFS(f_registered,f_hr,$B16),0) -> 48.5 | E16: =IFERROR(AVERAGEIFS(f_cnt,f_hr,$B16),0) -> 53.642857 | F16: =COUNTIFS(f_hr,$B16) -> 42 | G16: =SUMIFS(f_cnt,f_hr,$B16) -> 2253 | H16: =IFERROR(SUMIFS(f_casual,f_hr,$B16)/SUMIFS(f_cnt,f_hr,$B16),0) -> 0.09587217
B17: 11 | C17: =IFERROR(AVERAGEIFS(f_casual,f_hr,$B17),0) -> 8.7380952 | D17: =IFERROR(AVERAGEIFS(f_registered,f_hr,$B17),0) -> 50.642857 | E17: =IFERROR(AVERAGEIFS(f_cnt,f_hr,$B17),0) -> 59.380952 | F17: =COUNTIFS(f_hr,$B17) -> 42 | G17: =SUMIFS(f_cnt,f_hr,$B17) -> 2494 | H17: =IFERROR(SUMIFS(f_casual,f_hr,$B17)/SUMIFS(f_cnt,f_hr,$B17),0) -> 0.14715317
... B29: 23 | C29: =IFERROR(AVERAGEIFS(f_casual,f_hr,$B29),0) -> 2.3488372 | D29: =IFERROR(AVERAGEIFS(f_registered,f_hr,$B29),0) -> 22.837209 | E29: =IFERROR(AVERAGEIFS(f_cnt,f_hr,$B29),0) -> 25.186047 | F29: =COUNTIFS(f_hr,$B29) -> 43 | G29: =SUMIFS(f_cnt,f_hr,$B29) -> 1083 | H29: =IFERROR(SUMIFS(f_casual,f_hr,$B29)/SUMIFS(f_cnt,f_hr,$B29),0) -> 0.093259464
B32: 2. Demand by Day of Week
B33: Day | C33: Avg Casual | D33: Avg Registered | E33: Avg Total | F33: Hours | G33: Total Rentals | H33: Casual Share
B34: Mon | C34: =IFERROR(AVERAGEIFS(f_casual,f_Day_Name,$B34),0) -> 3.5838926 | D34: =IFERROR(AVERAGEIFS(f_registered,f_Day_Name,$B34),0) -> 53.127517 | E34: =IFERROR(AVERAGEIFS(f_cnt,f_Day_Name,$B34),0) -> 56.711409 | F34: =COUNTIFS(f_Day_Name,$B34) -> 149 | G34: =SUMIFS(f_cnt,f_Day_Name,$B34) -> 8450 | H34: =IFERROR(SUMIFS(f_casual,f_Day_Name,$B34)/SUMIFS(f_cnt,f_Day_Name,$B34),0) -> 0.063195266
B35: Tue | C35: =IFERROR(AVERAGEIFS(f_casual,f_Day_Name,$B35),0) -> 3.5984252 | D35: =IFERROR(AVERAGEIFS(f_registered,f_Day_Name,$B35),0) -> 62.409449 | E35: =IFERROR(AVERAGEIFS(f_cnt,f_Day_Name,$B35),0) -> 66.007874 | F35: =COUNTIFS(f_Day_Name,$B35) -> 127 | G35: =SUMIFS(f_cnt,f_Day_Name,$B35) -> 8383 | H35: =IFERROR(SUMIFS(f_casual,f_Day_Name,$B35)/SUMIFS(f_cnt,f_Day_Name,$B35),0) -> 0.05451509
B36: Wed | C36: =IFERROR(AVERAGEIFS(f_casual,f_Day_Name,$B36),0) -> 2.6259542 | D36: =IFERROR(AVERAGEIFS(f_registered,f_Day_Name,$B36),0) -> 58.816794 | E36: =IFERROR(AVERAGEIFS(f_cnt,f_Day_Name,$B36),0) -> 61.442748 | F36: =COUNTIFS(f_Day_Name,$B36) -> 131 | G36: =SUMIFS(f_cnt,f_Day_Name,$B36) -> 8049 | H36: =IFERROR(SUMIFS(f_casual,f_Day_Name,$B36)/SUMIFS(f_cnt,f_Day_Name,$B36),0) -> 0.042738228
B37: Thu | C37: =IFERROR(AVERAGEIFS(f_casual,f_Day_Name,$B37),0) -> 2.656 | D37: =IFERROR(AVERAGEIFS(f_registered,f_Day_Name,$B37),0) -> 65.008 | E37: =IFERROR(AVERAGEIFS(f_cnt,f_Day_Name,$B37),0) -> 67.664 | F37: =COUNTIFS(f_Day_Name,$B37) -> 125 | G37: =SUMIFS(f_cnt,f_Day_Name,$B37) -> 8458 | H37: =IFERROR(SUMIFS(f_casual,f_Day_Name,$B37)/SUMIFS(f_cnt,f_Day_Name,$B37),0) -> 0.039252778
B38: Fri | C38: =IFERROR(AVERAGEIFS(f_casual,f_Day_Name,$B38),0) -> 4 | D38: =IFERROR(AVERAGEIFS(f_registered,f_Day_Name,$B38),0) -> 61.905797 | E38: =IFERROR(AVERAGEIFS(f_cnt,f_Day_Name,$B38),0) -> 65.905797 | F38: =COUNTIFS(f_Day_Name,$B38) -> 138 | G38: =SUMIFS(f_cnt,f_Day_Name,$B38) -> 9095 | H38: =IFERROR(SUMIFS(f_casual,f_Day_Name,$B38)/SUMIFS(f_cnt,f_Day_Name,$B38),0) -> 0.060692688
B39: Sat | C39: =IFERROR(AVERAGEIFS(f_casual,f_Day_Name,$B39),0) -> 7.3795181 | D39: =IFERROR(AVERAGEIFS(f_registered,f_Day_Name,$B39),0) -> 39.295181 | E39: =IFERROR(AVERAGEIFS(f_cnt,f_Day_Name,$B39),0) -> 46.674699 | F39: =COUNTIFS(f_Day_Name,$B39) -> 166 | G39: =SUMIFS(f_cnt,f_Day_Name,$B39) -> 7748 | H39: =IFERROR(SUMIFS(f_casual,f_Day_Name,$B39)/SUMIFS(f_cnt,f_Day_Name,$B39),0) -> 0.15810532
B40: Sun | C40: =IFERROR(AVERAGEIFS(f_casual,f_Day_Name,$B40),0) -> 9.0060976 | D40: =IFERROR(AVERAGEIFS(f_registered,f_Day_Name,$B40),0) -> 40.512195 | E40: =IFERROR(AVERAGEIFS(f_cnt,f_Day_Name,$B40),0) -> 49.518293 | F40: =COUNTIFS(f_Day_Name,$B40) -> 164 | G40: =SUMIFS(f_cnt,f_Day_Name,$B40) -> 8121 | H40: =IFERROR(SUMIFS(f_casual,f_Day_Name,$B40)/SUMIFS(f_cnt,f_Day_Name,$B40),0) -> 0.18187415
B49: 3. Working vs Non-Working Day
B50: Day Category | C50: Avg Casual | D50: Avg Registered | E50: Avg Total | F50: Hours | G50: Total Rentals | H50: Casual Share
B51: Working Day | C51: =IFERROR(AVERAGEIFS(f_casual,f_Working_Day,$B51),0) -> 3.25387 | D51: =IFERROR(AVERAGEIFS(f_registered,f_Working_Day,$B51),0) -> 60.886997 | E51: =IFERROR(AVERAGEIFS(f_cnt,f_Working_Day,$B51),0) -> 64.140867 | F51: =COUNTIFS(f_Working_Day,$B51) -> 646 | G51: =SUMIFS(f_cnt,f_Working_Day,$B51) -> 41435 | H51: =IFERROR(SUMIFS(f_casual,f_Working_Day,$B51)/SUMIFS(f_cnt,f_Working_Day,$B51),0) -> 0.050730059
B52: Non-Working Day | C52: =IFERROR(AVERAGEIFS(f_casual,f_Working_Day,$B52),0) -> 7.9632768 | D52: =IFERROR(AVERAGEIFS(f_registered,f_Working_Day,$B52),0) -> 39.689266 | E52: =IFERROR(AVERAGEIFS(f_cnt,f_Working_Day,$B52),0) -> 47.652542 | F52: =COUNTIFS(f_Working_Day,$B52) -> 354 | G52: =SUMIFS(f_cnt,f_Working_Day,$B52) -> 16869 | H52: =IFERROR(SUMIFS(f_casual,f_Working_Day,$B52)/SUMIFS(f_cnt,f_Working_Day,$B52),0) -> 0.16711127
B66: 4. Demand by Weather
B67: Weather | C67: Avg Casual | D67: Avg Registered | E67: Avg Total | F67: Hours | G67: Total Rentals | H67: Casual Share
B68: Clear | C68: =IFERROR(AVERAGEIFS(f_casual,f_Weather,$B68),0) -> 5.2986799 | D68: =IFERROR(AVERAGEIFS(f_registered,f_Weather,$B68),0) -> 56.372937 | E68: =IFERROR(AVERAGEIFS(f_cnt,f_Weather,$B68),0) -> 61.671617 | F68: =COUNTIFS(f_Weather,$B68) -> 606 | G68: =SUMIFS(f_cnt,f_Weather,$B68) -> 37373 | H68: =IFERROR(SUMIFS(f_casual,f_Weather,$B68)/SUMIFS(f_cnt,f_Weather,$B68),0) -> 0.085917641
B69: Cloudy/Mist | C69: =IFERROR(AVERAGEIFS(f_casual,f_Weather,$B69),0) -> 4.9773463 | D69: =IFERROR(AVERAGEIFS(f_registered,f_Weather,$B69),0) -> 53.618123 | E69: =IFERROR(AVERAGEIFS(f_cnt,f_Weather,$B69),0) -> 58.595469 | F69: =COUNTIFS(f_Weather,$B69) -> 309 | G69: =SUMIFS(f_cnt,f_Weather,$B69) -> 18106 | H69: =IFERROR(SUMIFS(f_casual,f_Weather,$B69)/SUMIFS(f_cnt,f_Weather,$B69),0) -> 0.084944217
B70: Light Rain/Snow | C70: =IFERROR(AVERAGEIFS(f_casual,f_Weather,$B70),0) -> 2.0357143 | D70: =IFERROR(AVERAGEIFS(f_registered,f_Weather,$B70),0) -> 31.166667 | E70: =IFERROR(AVERAGEIFS(f_cnt,f_Weather,$B70),0) -> 33.202381 | F70: =COUNTIFS(f_Weather,$B70) -> 84 | G70: =SUMIFS(f_cnt,f_Weather,$B70) -> 2789 | H70: =IFERROR(SUMIFS(f_casual,f_Weather,$B70)/SUMIFS(f_cnt,f_Weather,$B70),0) -> 0.061312298
B71: Heavy Rain | C71: =IFERROR(AVERAGEIFS(f_casual,f_Weather,$B71),0) -> 1 | D71: =IFERROR(AVERAGEIFS(f_registered,f_Weather,$B71),0) -> 35 | E71: =IFERROR(AVERAGEIFS(f_cnt,f_Weather,$B71),0) -> 36 | F71: =COUNTIFS(f_Weather,$B71) -> 1 | G71: =SUMIFS(f_cnt,f_Weather,$B71) -> 36 | H71: =IFERROR(SUMIFS(f_casual,f_Weather,$B71)/SUMIFS(f_cnt,f_Weather,$B71),0) -> 0.027777778
B83: 5. Demand by Time Band
B84: Time Band | C84: Avg Casual | D84: Avg Registered | E84: Avg Total | F84: Hours | G84: Total Rentals | H84: Casual Share
B85: Night | C85: =IFERROR(AVERAGEIFS(f_casual,f_Time_Band,$B85),0) -> 0.86899563 | D85: =IFERROR(AVERAGEIFS(f_registered,f_Time_Band,$B85),0) -> 7.1703057 | E85: =IFERROR(AVERAGEIFS(f_cnt,f_Time_Band,$B85),0) -> 8.0393013 | F85: =COUNTIFS(f_Time_Band,$B85) -> 229 | G85: =SUMIFS(f_cnt,f_Time_Band,$B85) -> 1841 | H85: =IFERROR(SUMIFS(f_casual,f_Time_Band,$B85)/SUMIFS(f_cnt,f_Time_Band,$B85),0) -> 0.10809343
B86: Morning | C86: =IFERROR(AVERAGEIFS(f_casual,f_Time_Band,$B86),0) -> 3.8221344 | D86: =IFERROR(AVERAGEIFS(f_registered,f_Time_Band,$B86),0) -> 63.245059 | E86: =IFERROR(AVERAGEIFS(f_cnt,f_Time_Band,$B86),0) -> 67.067194 | F86: =COUNTIFS(f_Time_Band,$B86) -> 253 | G86: =SUMIFS(f_cnt,f_Time_Band,$B86) -> 16968 | H86: =IFERROR(SUMIFS(f_casual,f_Time_Band,$B86)/SUMIFS(f_cnt,f_Time_Band,$B86),0) -> 0.056989628
...

Sheet Stats
A1: Statistics & Excel Functions
A2: Basic, text, conditional and statistical functions on the final dataset (brief tasks 1, 3 and 4). All values are live formulas.
B4: Measure (cnt = rentals per hour) | C4: Value | D4: Formula used | F4: Text function | G4: Example input | H4: Result | I4: What it does
B5: Total rentals | C5: =SUM(f_cnt) -> 58304 | D5: SUM | F5: LEFT | G5: =Final_Dataset!Q2 -> REC-0001 | H5: =LEFT(G5,3) -> REC | I5: First 3 characters: the ID prefix
B6: Average rentals per hour | C6: =AVERAGE(f_cnt) -> 58.304 | D6: AVERAGE | F6: RIGHT | G6: =Final_Dataset!Q2 -> REC-0001 | H6: =RIGHT(G6,4) -> 0001 | I6: Last 4 characters: the number
B7: Number of hourly records | C7: =COUNT(f_cnt) -> 1000 | D7: COUNT | F7: LEN | G7: =Final_Dataset!Q2 -> REC-0001 | H7: =LEN(G7) -> 8 | I7: Length of the ID
B8: Median rentals per hour | C8: =MEDIAN(f_cnt) -> 49 | D8: MEDIAN | F8: UPPER | G8: =Final_Dataset!T2 -> Sat | H8: =UPPER(G8) -> SAT | I8: Day name in capitals
B9: Minimum rentals in an hour | C9: =MIN(f_cnt) -> 1 | D9: MIN | F9: TEXT | G9: =Final_Dataset!B2 -> 40544 | H9: =TEXT(G9,"dddd, dd mmm yyyy") -> Saturday, 01 Jan 2011 | I9: Formats a date as words
B10: Maximum rentals in an hour | C10: =MAX(f_cnt) -> 249 | D10: MAX | F10: CONCATENATE (&) | G10: =Final_Dataset!T2 -> Sat | H10: =G10&" | "&Final_Dataset!X2&" | "&Final_Dataset!F2&":00" -> Sat | Clear | 0:00 | I10: Joins fields into a label
B11: Std deviation (sample) | C11: =STDEV(f_cnt) -> 50.985558 | D11: STDEV
B12: Total registered rentals | C12: =SUM(f_registered) -> 53383 | D12: SUM
B13: Total casual rentals | C13: =SUM(f_casual) -> 4921 | D13: SUM
B14: Registered share | C14: =C12/C5 -> 0.91559756 | D14: ratio
B15: Hours with Clear weather | C15: =COUNTIF(f_Weather,"Clear") -> 606 | D15: COUNTIF
B16: Rentals on weekends | C16: =SUMIF(f_Day_Type,"Weekend",f_cnt) -> 15869 | D16: SUMIF
B17: Avg rentals: weekday hour | C17: =AVERAGEIF(f_Day_Type,"Weekday",f_cnt) -> 63.335821 | D17: AVERAGEIF
B18: Avg rentals: weekend hour | C18: =AVERAGEIF(f_Day_Type,"Weekend",f_cnt) -> 48.087879 | D18: AVERAGEIF
B19: Rentals in weekday peak hours | C19: =SUMIFS(f_cnt,f_Peak_Hour,"Peak") -> 25431 | D19: SUMIFS
B20: Share of all rentals in peak hours | C20: =C19/C5 -> 0.43617934 | D20: ratio
B21: High-demand hours (>= P75) | C21: =COUNTIF(f_Demand_Level,"High") -> 259 | D21: COUNTIF
B22: Correlation temp vs cnt | C22: =CORREL(f_temp,f_cnt) -> 0.22929155 | D22: CORREL
B23: Correlation humidity vs cnt | C23: =CORREL(f_hum,f_cnt) -> -0.2543533 | D23: CORREL
B24: Correlation registered vs cnt | C24: =CORREL(f_registered,f_cnt) -> 0.98999319 | D24: CORREL
B28: Demand thresholds
B29: 25th percentile of cnt (Low threshold) | C29: =QUARTILE(f_cnt,1) -> 16 | D29: QUARTILE
B30: 75th percentile of cnt (High threshold) | C30: =QUARTILE(f_cnt,3) -> 83 | D30: QUARTILE
B32: Descriptive Statistics
B33: Statistic | C33: temp | D33: atemp | E33: hum | F33: windspeed | G33: casual | H33: registered | I33: cnt
B34: Mean | C34: =AVERAGE(f_temp) -> 0.2059 | D34: =AVERAGE(f_atemp) -> 0.2130204 | E34: =AVERAGE(f_hum) -> 0.58248 | F34: =AVERAGE(f_windspeed) -> 0.1949313 | G34: =AVERAGE(f_casual) -> 4.921 | H34: =AVERAGE(f_registered) -> 53.383 | I34: =AVERAGE(f_cnt) -> 58.304
B35: Median | C35: =MEDIAN(f_temp) -> 0.2 | D35: =MEDIAN(f_atemp) -> 0.2121 | E35: =MEDIAN(f_hum) -> 0.55 | F35: =MEDIAN(f_windspeed) -> 0.1642 | G35: =MEDIAN(f_casual) -> 3 | H35: =MEDIAN(f_registered) -> 46 | I35: =MEDIAN(f_cnt) -> 49
B36: Mode | C36: =MODE(f_temp) -> 0.22 | D36: =MODE(f_atemp) -> 0.2273 | E36: =MODE(f_hum) -> 0.93 | F36: =MODE(f_windspeed) -> 0 | G36: =MODE(f_casual) -> 0 | H36: =MODE(f_registered) -> 1 | I36: =MODE(f_cnt) -> 1
B37: Std Deviation | C37: =STDEV(f_temp) -> 0.078977386 | D37: =STDEV(f_atemp) -> 0.077590772 | E37: =STDEV(f_hum) -> 0.18797709 | F37: =STDEV(f_windspeed) -> 0.12912607 | G37: =STDEV(f_casual) -> 7.6438988 | H37: =STDEV(f_registered) -> 47.893968 | I37: =STDEV(f_cnt) -> 50.985558
B38: Variance | C38: =VAR(f_temp) -> 0.0062374274 | D38: =VAR(f_atemp) -> 0.0060203279 | E38: =VAR(f_hum) -> 0.035335385 | F38: =VAR(f_windspeed) -> 0.016673541 | G38: =VAR(f_casual) -> 58.429188 | H38: =VAR(f_registered) -> 2293.8321 | I38: =VAR(f_cnt) -> 2599.5271
B39: Skewness | C39: =SKEW(f_temp) -> 0.54799688 | D39: =SKEW(f_atemp) -> 0.45310412 | E39: =SKEW(f_hum) -> 0.43689346 | F39: =SKEW(f_windspeed) -> 0.43367506 | G39: =SKEW(f_casual) -> 3.414105 | H39: =SKEW(f_registered) -> 1.2967233 | I39: =SKEW(f_cnt) -> 1.1377091
B40: Kurtosis | C40: =KURT(f_temp) -> 0.77506113 | D40: =KURT(f_atemp) -> 0.66738552 | E40: =KURT(f_hum) -> -0.72312265 | F40: =KURT(f_windspeed) -> -0.20985336 | G40: =KURT(f_casual) -> 15.09774 | H40: =KURT(f_registered) -> 1.6425063 | I40: =KURT(f_cnt) -> 1.0266606
B41: Minimum | C41: =MIN(f_temp) -> 0.02 | D41: =MIN(f_atemp) -> 0 | E41: =MIN(f_hum) -> 0.21 | F41: =MIN(f_windspeed) -> 0 | G41: =MIN(f_casual) -> 0 | H41: =MIN(f_registered) -> 0 | I41: =MIN(f_cnt) -> 1
B42: 1st Quartile | C42: =QUARTILE(f_temp,1) -> 0.16 | D42: =QUARTILE(f_atemp,1) -> 0.1667 | E42: =QUARTILE(f_hum,1) -> 0.44 | F42: =QUARTILE(f_windspeed,1) -> 0.1045 | G42: =QUARTILE(f_casual,1) -> 0 | H42: =QUARTILE(f_registered,1) -> 15 | I42: =QUARTILE(f_cnt,1) -> 16
B43: 3rd Quartile | C43: =QUARTILE(f_temp,3) -> 0.24 | D43: =QUARTILE(f_atemp,3) -> 0.2576 | E43: =QUARTILE(f_hum,3) -> 0.7 | F43: =QUARTILE(f_windspeed,3) -> 0.2836 | G43: =QUARTILE(f_casual,3) -> 6 | H43: =QUARTILE(f_registered,3) -> 74 | I43: =QUARTILE(f_cnt,3) -> 83
B44: Maximum | C44: =MAX(f_temp) -> 0.46 | D44: =MAX(f_atemp) -> 0.4545 | E44: =MAX(f_hum) -> 1 | F44: =MAX(f_windspeed) -> 0.5821 | G44: =MAX(f_casual) -> 62 | H44: =MAX(f_registered) -> 247 | I44: =MAX(f_cnt) -> 249
B45: Range | C45: =MAX(f_temp)-MIN(f_temp) -> 0.44 | D45: =MAX(f_atemp)-MIN(f_atemp) -> 0.4545 | E45: =MAX(f_hum)-MIN(f_hum) -> 0.79 | F45: =MAX(f_windspeed)-MIN(f_windspeed) -> 0.5821 | G45: =MAX(f_casual)-MIN(f_casual) -> 62 | H45: =MAX(f_registered)-MIN(f_registered) -> 247 | I45: =MAX(f_cnt)-MIN(f_cnt) -> 248
...

Sheet Anomalies
A1: Anomaly Detection: Hourly Rentals
A2: Each hour is compared with the normal demand for the SAME hour of day (Z-score), so ordinary rush-hour peaks are not flagged.
A4: Z-score threshold (±) | B4: 3 | D4: Hour | E4: Obs | F4: Mean cnt | G4: StDev cnt | H4: Upper limit | I4: Lower limit | J4: Flagged
D5: 0 | E5: =COUNTIF(f_hr,D5) -> 43 | F5: =AVERAGEIF(f_hr,D5,f_cnt) -> 16.348837 | G5: =SQRT(SUMPRODUCT((f_hr=D5)*(f_cnt-F5)^2)/(E5-1)) -> 10.442322 | H5: =F5+$B$4*G5 -> 47.675802 | I5: =MAX(0,F5-$B$4*G5) -> 0 | J5: =COUNTIFS($C$31:$C$1030,D5,$M$31:$M$1030,"?*") -> 0
A6: Hours analysed | B6: =COUNT(I31:I1030) -> 1000 | D6: 1 | E6: =COUNTIF(f_hr,D6) -> 43 | F6: =AVERAGEIF(f_hr,D6,f_cnt) -> 10.697674 | G6: =SQRT(SUMPRODUCT((f_hr=D6)*(f_cnt-F6)^2)/(E6-1)) -> 10.060614 | H6: =F6+$B$4*G6 -> 40.879515 | I6: =MAX(0,F6-$B$4*G6) -> 0 | J6: =COUNTIFS($C$31:$C$1030,D6,$M$31:$M$1030,"?*") -> 1
A7: High anomalies (unusually busy) | B7: =COUNTIF(M31:M1030,"High") -> 7 | D7: 2 | E7: =COUNTIF(f_hr,D7) -> 41 | F7: =AVERAGEIF(f_hr,D7,f_cnt) -> 7.1707317 | G7: =SQRT(SUMPRODUCT((f_hr=D7)*(f_cnt-F7)^2)/(E7-1)) -> 7.3685224 | H7: =F7+$B$4*G7 -> 29.276299 | I7: =MAX(0,F7-$B$4*G7) -> 0 | J7: =COUNTIFS($C$31:$C$1030,D7,$M$31:$M$1030,"?*") -> 1
A8: Low anomalies (unusually quiet) | B8: =COUNTIF(M31:M1030,"Low") -> 0 | D8: 3 | E8: =COUNTIF(f_hr,D8) -> 31 | F8: =AVERAGEIF(f_hr,D8,f_cnt) -> 4.8709677 | G8: =SQRT(SUMPRODUCT((f_hr=D8)*(f_cnt-F8)^2)/(E8-1)) -> 4.470212 | H8: =F8+$B$4*G8 -> 18.281604 | I8: =MAX(0,F8-$B$4*G8) -> 0 | J8: =COUNTIFS($C$31:$C$1030,D8,$M$31:$M$1030,"?*") -> 0
A9: % of hours flagged | B9: =IF(B6=0,0,(B7+B8)/B6) -> 0.007 | D9: 4 | E9: =COUNTIF(f_hr,D9) -> 32 | F9: =AVERAGEIF(f_hr,D9,f_cnt) -> 2.15625 | G9: =SQRT(SUMPRODUCT((f_hr=D9)*(f_cnt-F9)^2)/(E9-1)) -> 1.5263149 | H9: =F9+$B$4*G9 -> 6.7351946 | I9: =MAX(0,F9-$B$4*G9) -> 0 | J9: =COUNTIFS($C$31:$C$1030,D9,$M$31:$M$1030,"?*") -> 1
D10: 5 | E10: =COUNTIF(f_hr,D10) -> 39 | F10: =AVERAGEIF(f_hr,D10,f_cnt) -> 4.2051282 | G10: =SQRT(SUMPRODUCT((f_hr=D10)*(f_cnt-F10)^2)/(E10-1)) -> 2.5358429 | H10: =F10+$B$4*G10 -> 11.812657 | I10: =MAX(0,F10-$B$4*G10) -> 0 | J10: =COUNTIFS($C$31:$C$1030,D10,$M$31:$M$1030,"?*") -> 0
D11: 6 | E11: =COUNTIF(f_hr,D11) -> 42 | F11: =AVERAGEIF(f_hr,D11,f_cnt) -> 19.571429 | G11: =SQRT(SUMPRODUCT((f_hr=D11)*(f_cnt-F11)^2)/(E11-1)) -> 14.202615 | H11: =F11+$B$4*G11 -> 62.179275 | I11: =MAX(0,F11-$B$4*G11) -> 0 | J11: =COUNTIFS($C$31:$C$1030,D11,$M$31:$M$1030,"?*") -> 0
D12: 7 | E12: =COUNTIF(f_hr,D12) -> 43 | F12: =AVERAGEIF(f_hr,D12,f_cnt) -> 54.395349 | G12: =SQRT(SUMPRODUCT((f_hr=D12)*(f_cnt-F12)^2)/(E12-1)) -> 39.112864 | H12: =F12+$B$4*G12 -> 171.73394 | I12: =MAX(0,F12-$B$4*G12) -> 0 | J12: =COUNTIFS($C$31:$C$1030,D12,$M$31:$M$1030,"?*") -> 0
D13: 8 | E13: =COUNTIF(f_hr,D13) -> 42 | F13: =AVERAGEIF(f_hr,D13,f_cnt) -> 128.28571 | G13: =SQRT(SUMPRODUCT((f_hr=D13)*(f_cnt-F13)^2)/(E13-1)) -> 88.551566 | H13: =F13+$B$4*G13 -> 393.94041 | I13: =MAX(0,F13-$B$4*G13) -> 0 | J13: =COUNTIFS($C$31:$C$1030,D13,$M$31:$M$1030,"?*") -> 0
D14: 9 | E14: =COUNTIF(f_hr,D14) -> 42 | F14: =AVERAGEIF(f_hr,D14,f_cnt) -> 87.428571 | G14: =SQRT(SUMPRODUCT((f_hr=D14)*(f_cnt-F14)^2)/(E14-1)) -> 45.938529 | H14: =F14+$B$4*G14 -> 225.24416 | I14: =MAX(0,F14-$B$4*G14) -> 0 | J14: =COUNTIFS($C$31:$C$1030,D14,$M$31:$M$1030,"?*") -> 0
D15: 10 | E15: =COUNTIF(f_hr,D15) -> 42 | F15: =AVERAGEIF(f_hr,D15,f_cnt) -> 53.642857 | G15: =SQRT(SUMPRODUCT((f_hr=D15)*(f_cnt-F15)^2)/(E15-1)) -> 15.395314 | H15: =F15+$B$4*G15 -> 99.828798 | I15: =MAX(0,F15-$B$4*G15) -> 7.4569165 | J15: =COUNTIFS($C$31:$C$1030,D15,$M$31:$M$1030,"?*") -> 1
D16: 11 | E16: =COUNTIF(f_hr,D16) -> 42 | F16: =AVERAGEIF(f_hr,D16,f_cnt) -> 59.380952 | G16: =SQRT(SUMPRODUCT((f_hr=D16)*(f_cnt-F16)^2)/(E16-1)) -> 20.895737 | H16: =F16+$B$4*G16 -> 122.06816 | I16: =MAX(0,F16-$B$4*G16) -> 0 | J16: =COUNTIFS($C$31:$C$1030,D16,$M$31:$M$1030,"?*") -> 0
D17: 12 | E17: =COUNTIF(f_hr,D17) -> 43 | F17: =AVERAGEIF(f_hr,D17,f_cnt) -> 76.348837 | G17: =SQRT(SUMPRODUCT((f_hr=D17)*(f_cnt-F17)^2)/(E17-1)) -> 29.034367 | H17: =F17+$B$4*G17 -> 163.45194 | I17: =MAX(0,F17-$B$4*G17) -> 0 | J17: =COUNTIFS($C$31:$C$1030,D17,$M$31:$M$1030,"?*") -> 1
D18: 13 | E18: =COUNTIF(f_hr,D18) -> 43 | F18: =AVERAGEIF(f_hr,D18,f_cnt) -> 78.511628 | G18: =SQRT(SUMPRODUCT((f_hr=D18)*(f_cnt-F18)^2)/(E18-1)) -> 30.07243 | H18: =F18+$B$4*G18 -> 168.72892 | I18: =MAX(0,F18-$B$4*G18) -> 0 | J18: =COUNTIFS($C$31:$C$1030,D18,$M$31:$M$1030,"?*") -> 1
D19: 14 | E19: =COUNTIF(f_hr,D19) -> 43 | F19: =AVERAGEIF(f_hr,D19,f_cnt) -> 74.418605 | G19: =SQRT(SUMPRODUCT((f_hr=D19)*(f_cnt-F19)^2)/(E19-1)) -> 30.305769 | H19: =F19+$B$4*G19 -> 165.33591 | I19: =MAX(0,F19-$B$4*G19) -> 0 | J19: =COUNTIFS($C$31:$C$1030,D19,$M$31:$M$1030,"?*") -> 0
D20: 15 | E20: =COUNTIF(f_hr,D20) -> 43 | F20: =AVERAGEIF(f_hr,D20,f_cnt) -> 77.953488 | G20: =SQRT(SUMPRODUCT((f_hr=D20)*(f_cnt-F20)^2)/(E20-1)) -> 34.481157 | H20: =F20+$B$4*G20 -> 181.39696 | I20: =MAX(0,F20-$B$4*G20) -> 0 | J20: =COUNTIFS($C$31:$C$1030,D20,$M$31:$M$1030,"?*") -> 1
D21: 16 | E21: =COUNTIF(f_hr,D21) -> 44 | F21: =AVERAGEIF(f_hr,D21,f_cnt) -> 89.272727 | G21: =SQRT(SUMPRODUCT((f_hr=D21)*(f_cnt-F21)^2)/(E21-1)) -> 25.461657 | H21: =F21+$B$4*G21 -> 165.6577 | I21: =MAX(0,F21-$B$4*G21) -> 12.887756 | J21: =COUNTIFS($C$31:$C$1030,D21,$M$31:$M$1030,"?*") -> 0
... D28: 23 | E28: =COUNTIF(f_hr,D28) -> 43 | F28: =AVERAGEIF(f_hr,D28,f_cnt) -> 25.186047 | G28: =SQRT(SUMPRODUCT((f_hr=D28)*(f_cnt-F28)^2)/(E28-1)) -> 11.751911 | H28: =F28+$B$4*G28 -> 60.44178 | I28: =MAX(0,F28-$B$4*G28) -> 0 | J28: =COUNTIFS($C$31:$C$1030,D28,$M$31:$M$1030,"?*") -> 0
A29: Row-level detail (orange row = flagged). Use the filter arrows to show only flagged hours.
A30: Instant | B30: Date | C30: Hour | D30: Day | E30: Weather | F30: Temp | G30: Humidity | H30: Windspeed | I30: cnt | J30: Hour mean | K30: Hour StDev | L30: Z-score | M30: Flag
A31: =Final_Dataset!A2 -> 1 | B31: =Final_Dataset!B2 -> 40544 | C31: =Final_Dataset!F2 -> 0 | D31: =Final_Dataset!T2 -> Sat | E31: =Final_Dataset!X2 -> Clear | F31: =Final_Dataset!J2 -> 0.24 | G31: =Final_Dataset!L2 -> 0.81 | H31: =Final_Dataset!M2 -> 0 | I31: =Final_Dataset!P2 -> 16 | J31: =INDEX($F$5:$F$28,MATCH(C31,$D$5:$D$28,0)) -> 16.348837 | K31: =INDEX($G$5:$G$28,MATCH(C31,$D$5:$D$28,0)) -> 10.442322 | L31: =IF(K31=0,0,(I31-J31)/K31) -> -0.033406097 | M31: =IF(ABS(L31)>=$B$4,IF(L31>0,"High","Low"),"")
A32: =Final_Dataset!A3 -> 2 | B32: =Final_Dataset!B3 -> 40544 | C32: =Final_Dataset!F3 -> 1 | D32: =Final_Dataset!T3 -> Sat | E32: =Final_Dataset!X3 -> Clear | F32: =Final_Dataset!J3 -> 0.22 | G32: =Final_Dataset!L3 -> 0.8 | H32: =Final_Dataset!M3 -> 0 | I32: =Final_Dataset!P3 -> 40 | J32: =INDEX($F$5:$F$28,MATCH(C32,$D$5:$D$28,0)) -> 10.697674 | K32: =INDEX($G$5:$G$28,MATCH(C32,$D$5:$D$28,0)) -> 10.060614 | L32: =IF(K32=0,0,(I32-J32)/K32) -> 2.9125784 | M32: =IF(ABS(L32)>=$B$4,IF(L32>0,"High","Low"),"")
A33: =Final_Dataset!A4 -> 3 | B33: =Final_Dataset!B4 -> 40544 | C33: =Final_Dataset!F4 -> 2 | D33: =Final_Dataset!T4 -> Sat | E33: =Final_Dataset!X4 -> Clear | F33: =Final_Dataset!J4 -> 0.22 | G33: =Final_Dataset!L4 -> 0.8 | H33: =Final_Dataset!M4 -> 0 | I33: =Final_Dataset!P4 -> 32 | J33: =INDEX($F$5:$F$28,MATCH(C33,$D$5:$D$28,0)) -> 7.1707317 | K33: =INDEX($G$5:$G$28,MATCH(C33,$D$5:$D$28,0)) -> 7.3685224 | L33: =IF(K33=0,0,(I33-J33)/K33) -> 3.3696401 | M33: =IF(ABS(L33)>=$B$4,IF(L33>0,"High","Low"),"") -> High
A34: =Final_Dataset!A5 -> 4 | B34: =Final_Dataset!B5 -> 40544 | C34: =Final_Dataset!F5 -> 3 | D34: =Final_Dataset!T5 -> Sat | E34: =Final_Dataset!X5 -> Clear | F34: =Final_Dataset!J5 -> 0.24 | G34: =Final_Dataset!L5 -> 0.75 | H34: =Final_Dataset!M5 -> 0 | I34: =Final_Dataset!P5 -> 13 | J34: =INDEX($F$5:$F$28,MATCH(C34,$D$5:$D$28,0)) -> 4.8709677 | K34: =INDEX($G$5:$G$28,MATCH(C34,$D$5:$D$28,0)) -> 4.470212 | L34: =IF(K34=0,0,(I34-J34)/K34) -> 1.8184892 | M34: =IF(ABS(L34)>=$B$4,IF(L34>0,"High","Low"),"")
A35: =Final_Dataset!A6 -> 5 | B35: =Final_Dataset!B6 -> 40544 | C35: =Final_Dataset!F6 -> 4 | D35: =Final_Dataset!T6 -> Sat | E35: =Final_Dataset!X6 -> Clear | F35: =Final_Dataset!J6 -> 0.24 | G35: =Final_Dataset!L6 -> 0.75 | H35: =Final_Dataset!M6 -> 0 | I35: =Final_Dataset!P6 -> 1 | J35: =INDEX($F$5:$F$28,MATCH(C35,$D$5:$D$28,0)) -> 2.15625 | K35: =INDEX($G$5:$G$28,MATCH(C35,$D$5:$D$28,0)) -> 1.5263149 | L35: =IF(K35=0,0,(I35-J35)/K35) -> -0.75754356 | M35: =IF(ABS(L35)>=$B$4,IF(L35>0,"High","Low"),"")
A36: =Final_Dataset!A7 -> 6 | B36: =Final_Dataset!B7 -> 40544 | C36: =Final_Dataset!F7 -> 5 | D36: =Final_Dataset!T7 -> Sat | E36: =Final_Dataset!X7 -> Cloudy/Mist | F36: =Final_Dataset!J7 -> 0.24 | G36: =Final_Dataset!L7 -> 0.75 | H36: =Final_Dataset!M7 -> 0.0896 | I36: =Final_Dataset!P7 -> 1 | J36: =INDEX($F$5:$F$28,MATCH(C36,$D$5:$D$28,0)) -> 4.2051282 | K36: =INDEX($G$5:$G$28,MATCH(C36,$D$5:$D$28,0)) -> 2.5358429 | L36: =IF(K36=0,0,(I36-J36)/K36) -> -1.2639301 | M36: =IF(ABS(L36)>=$B$4,IF(L36>0,"High","Low"),"")
A37: =Final_Dataset!A8 -> 7 | B37: =Final_Dataset!B8 -> 40544 | C37: =Final_Dataset!F8 -> 6 | D37: =Final_Dataset!T8 -> Sat | E37: =Final_Dataset!X8 -> Clear | F37: =Final_Dataset!J8 -> 0.22 | G37: =Final_Dataset!L8 -> 0.8 | H37: =Final_Dataset!M8 -> 0 | I37: =Final_Dataset!P8 -> 2 | J37: =INDEX($F$5:$F$28,MATCH(C37,$D$5:$D$28,0)) -> 19.571429 | K37: =INDEX($G$5:$G$28,MATCH(C37,$D$5:$D$28,0)) -> 14.202615 | L37: =IF(K37=0,0,(I37-J37)/K37) -> -1.2371967 | M37: =IF(ABS(L37)>=$B$4,IF(L37>0,"High","Low"),"")
A38: =Final_Dataset!A9 -> 8 | B38: =Final_Dataset!B9 -> 40544 | C38: =Final_Dataset!F9 -> 7 | D38: =Final_Dataset!T9 -> Sat | E38: =Final_Dataset!X9 -> Clear | F38: =Final_Dataset!J9 -> 0.2 | G38: =Final_Dataset!L9 -> 0.86 | H38: =Final_Dataset!M9 -> 0 | I38: =Final_Dataset!P9 -> 3 | J38: =INDEX($F$5:$F$28,MATCH(C38,$D$5:$D$28,0)) -> 54.395349 | K38: =INDEX($G$5:$G$28,MATCH(C38,$D$5:$D$28,0)) -> 39.112864 | L38: =IF(K38=0,0,(I38-J38)/K38) -> -1.3140267 | M38: =IF(ABS(L38)>=$B$4,IF(L38>0,"High","Low"),"")
A39: =Final_Dataset!A10 -> 9 | B39: =Final_Dataset!B10 -> 40544 | C39: =Final_Dataset!F10 -> 8 | D39: =Final_Dataset!T10 -> Sat | E39: =Final_Dataset!X10 -> Clear | F39: =Final_Dataset!J10 -> 0.24 | G39: =Final_Dataset!L10 -> 0.75 | H39: =Final_Dataset!M10 -> 0 | I39: =Final_Dataset!P10 -> 8 | J39: =INDEX($F$5:$F$28,MATCH(C39,$D$5:$D$28,0)) -> 128.28571 | K39: =INDEX($G$5:$G$28,MATCH(C39,$D$5:$D$28,0)) -> 88.551566 | L39: =IF(K39=0,0,(I39-J39)/K39) -> -1.3583691 | M39: =IF(ABS(L39)>=$B$4,IF(L39>0,"High","Low"),"")
A40: =Final_Dataset!A11 -> 10 | B40: =Final_Dataset!B11 -> 40544 | C40: =Final_Dataset!F11 -> 9 | D40: =Final_Dataset!T11 -> Sat | E40: =Final_Dataset!X11 -> Clear | F40: =Final_Dataset!J11 -> 0.32 | G40: =Final_Dataset!L11 -> 0.76 | H40: =Final_Dataset!M11 -> 0 | I40: =Final_Dataset!P11 -> 14 | J40: =INDEX($F$5:$F$28,MATCH(C40,$D$5:$D$28,0)) -> 87.428571 | K40: =INDEX($G$5:$G$28,MATCH(C40,$D$5:$D$28,0)) -> 45.938529 | L40: =IF(K40=0,0,(I40-J40)/K40) -> -1.5984093 | M40: =IF(ABS(L40)>=$B$4,IF(L40>0,"High","Low"),"")
A41: =Final_Dataset!A12 -> 11 | B41: =Final_Dataset!B12 -> 40544 | C41: =Final_Dataset!F12 -> 10 | D41: =Final_Dataset!T12 -> Sat | E41: =Final_Dataset!X12 -> Clear | F41: =Final_Dataset!J12 -> 0.38 | G41: =Final_Dataset!L12 -> 0.76 | H41: =Final_Dataset!M12 -> 0.2537 | I41: =Final_Dataset!P12 -> 36 | J41: =INDEX($F$5:$F$28,MATCH(C41,$D$5:$D$28,0)) -> 53.642857 | K41: =INDEX($G$5:$G$28,MATCH(C41,$D$5:$D$28,0)) -> 15.395314 | L41: =IF(K41=0,0,(I41-J41)/K41) -> -1.1459888 | M41: =IF(ABS(L41)>=$B$4,IF(L41>0,"High","Low"),"")
A42: =Final_Dataset!A13 -> 12 | B42: =Final_Dataset!B13 -> 40544 | C42: =Final_Dataset!F13 -> 11 | D42: =Final_Dataset!T13 -> Sat | E42: =Final_Dataset!X13 -> Clear | F42: =Final_Dataset!J13 -> 0.36 | G42: =Final_Dataset!L13 -> 0.81 | H42: =Final_Dataset!M13 -> 0.2836 | I42: =Final_Dataset!P13 -> 56 | J42: =INDEX($F$5:$F$28,MATCH(C42,$D$5:$D$28,0)) -> 59.380952 | K42: =INDEX($G$5:$G$28,MATCH(C42,$D$5:$D$28,0)) -> 20.895737 | L42: =IF(K42=0,0,(I42-J42)/K42) -> -0.16180106 | M42: =IF(ABS(L42)>=$B$4,IF(L42>0,"High","Low"),"")
... A1030: =Final_Dataset!A1001 -> 1000 | B1030: =Final_Dataset!B1001 -> 40588 | C1030: =Final_Dataset!F1001 -> 7 | D1030: =Final_Dataset!T1001 -> Mon | E1030: =Final_Dataset!X1001 -> Clear | F1030: =Final_Dataset!J1001 -> 0.34 | G1030: =Final_Dataset!L1001 -> 0.46 | H1030: =Final_Dataset!M1001 -> 0.2985 | I1030: =Final_Dataset!P1001 -> 98 | J1030: =INDEX($F$5:$F$28,MATCH(C1030,$D$5:$D$28,0)) -> 54.395349 | K1030: =INDEX($G$5:$G$28,MATCH(C1030,$D$5:$D$28,0)) -> 39.112864 | L1030: =IF(K1030=0,0,(I1030-J1030)/K1030) -> 1.1148417 | M1030: =IF(ABS(L1030)>=$B$4,IF(L1030>0,"High","Low"),"")

Sheet Forecast
A1: Forecast: Next 48 Hours of Rentals
A2: Excel's FORECAST.ETS (the engine behind Data > Forecast Sheet): exponential smoothing with a 24-hour daily cycle, 95% confidence band.
A4: Seasonality (hours) | B4: 24 | D4: Alpha (level) | E4: =_xlfn.FORECAST.ETS.STAT($C$15:$C$1014,$B$15:$B$1014,1,$B$4,$B$6,$B$7) -> 0.9
A5: Confidence level | B5: 0.95 | D5: Beta (trend) | E5: =_xlfn.FORECAST.ETS.STAT($C$15:$C$1014,$B$15:$B$1014,2,$B$4,$B$6,$B$7) -> 0.001
A6: Data completion (1 = interpolate gaps) | B6: 1 | D6: Gamma (seasonality) | E6: =_xlfn.FORECAST.ETS.STAT($C$15:$C$1014,$B$15:$B$1014,3,$B$4,$B$6,$B$7) -> 0.099
A7: Aggregation (1 = average) | B7: 1 | D7: MASE | E7: =_xlfn.FORECAST.ETS.STAT($C$15:$C$1014,$B$15:$B$1014,4,$B$4,$B$6,$B$7) -> 0.98020974
D8: SMAPE | E8: =_xlfn.FORECAST.ETS.STAT($C$15:$C$1014,$B$15:$B$1014,5,$B$4,$B$6,$B$7) -> 0.49510302
